2023-03-14 11:27:21,000 DEBUG Starting new HTTPS connection (1): en.wikipedia.org:443
2023-03-14 11:27:23,148 DEBUG https://en.wikipedia.org:443 "GET /w/api.php HTTP/1.1" 200 None
2023-03-14 11:27:23,188 INFO [31m[1mWARNING: This is a development server. Do not use it in a production deployment. Use a production WSGI server instead.[0m
 * Running on http://127.0.0.1:5000
2023-03-14 11:27:23,189 INFO [33mPress CTRL+C to quit[0m
2023-03-14 11:27:23,192 INFO  * Restarting with stat
2023-03-14 11:27:28,741 DEBUG Starting new HTTPS connection (1): en.wikipedia.org:443
2023-03-14 11:27:30,424 DEBUG https://en.wikipedia.org:443 "GET /w/api.php HTTP/1.1" 200 None
2023-03-14 11:27:30,473 WARNING  * Debugger is active!
2023-03-14 11:27:30,626 INFO  * Debugger PIN: 220-726-321
2023-03-14 11:27:48,711 INFO No data in query, wiki.html has loaded
2023-03-14 11:27:48,743 INFO 127.0.0.1 - - [14/Mar/2023 11:27:48] "GET / HTTP/1.1" 200 -
2023-03-14 11:28:13,783 DEBUG Starting new HTTPS connection (1): en.wikipedia.org:443
2023-03-14 11:28:14,253 ERROR issues loading the data HTTPSConnectionPool(host='en.wikipedia.org', port=443): Max retries exceeded with url: /w/api.php?action=query&format=json&list=search&srsearch=mom (Caused by SSLError(SSLCertVerificationError(1, '[SSL: CERTIFICATE_VERIFY_FAILED] certificate verify failed: unable to get local issuer certificate (_ssl.c:997)')))
Traceback (most recent call last):
  File "C:\Users\E1002312\AppData\Local\Programs\Python\Python310\lib\site-packages\urllib3\connectionpool.py", line 703, in urlopen
    httplib_response = self._make_request(
  File "C:\Users\E1002312\AppData\Local\Programs\Python\Python310\lib\site-packages\urllib3\connectionpool.py", line 386, in _make_request
    self._validate_conn(conn)
  File "C:\Users\E1002312\AppData\Local\Programs\Python\Python310\lib\site-packages\urllib3\connectionpool.py", line 1042, in _validate_conn
    conn.connect()
  File "C:\Users\E1002312\AppData\Local\Programs\Python\Python310\lib\site-packages\urllib3\connection.py", line 419, in connect
    self.sock = ssl_wrap_socket(
  File "C:\Users\E1002312\AppData\Local\Programs\Python\Python310\lib\site-packages\urllib3\util\ssl_.py", line 449, in ssl_wrap_socket
    ssl_sock = _ssl_wrap_socket_impl(
  File "C:\Users\E1002312\AppData\Local\Programs\Python\Python310\lib\site-packages\urllib3\util\ssl_.py", line 493, in _ssl_wrap_socket_impl
    return ssl_context.wrap_socket(sock, server_hostname=server_hostname)
  File "C:\Users\E1002312\AppData\Local\Programs\Python\Python310\lib\ssl.py", line 513, in wrap_socket
    return self.sslsocket_class._create(
  File "C:\Users\E1002312\AppData\Local\Programs\Python\Python310\lib\ssl.py", line 1071, in _create
    self.do_handshake()
  File "C:\Users\E1002312\AppData\Local\Programs\Python\Python310\lib\ssl.py", line 1342, in do_handshake
    self._sslobj.do_handshake()
ssl.SSLCertVerificationError: [SSL: CERTIFICATE_VERIFY_FAILED] certificate verify failed: unable to get local issuer certificate (_ssl.c:997)

During handling of the above exception, another exception occurred:

Traceback (most recent call last):
  File "C:\Users\E1002312\AppData\Local\Programs\Python\Python310\lib\site-packages\requests\adapters.py", line 489, in send
    resp = conn.urlopen(
  File "C:\Users\E1002312\AppData\Local\Programs\Python\Python310\lib\site-packages\urllib3\connectionpool.py", line 787, in urlopen
    retries = retries.increment(
  File "C:\Users\E1002312\AppData\Local\Programs\Python\Python310\lib\site-packages\urllib3\util\retry.py", line 592, in increment
    raise MaxRetryError(_pool, url, error or ResponseError(cause))
urllib3.exceptions.MaxRetryError: HTTPSConnectionPool(host='en.wikipedia.org', port=443): Max retries exceeded with url: /w/api.php?action=query&format=json&list=search&srsearch=mom (Caused by SSLError(SSLCertVerificationError(1, '[SSL: CERTIFICATE_VERIFY_FAILED] certificate verify failed: unable to get local issuer certificate (_ssl.c:997)')))

During handling of the above exception, another exception occurred:

Traceback (most recent call last):
  File "C:\Users\E1002312\OneDrive - Sanlam Life Insurance Limited\Desktop\SM Khama\Python-Flask\app.py", line 25, in home
    data = requests.get(URL,params={'action': 'query', 'format': 'json', 'list': 'search', 'srsearch': request.args.get('q')})
  File "C:\Users\E1002312\AppData\Local\Programs\Python\Python310\lib\site-packages\requests\api.py", line 73, in get
    return request("get", url, params=params, **kwargs)
  File "C:\Users\E1002312\AppData\Local\Programs\Python\Python310\lib\site-packages\requests\api.py", line 59, in request
    return session.request(method=method, url=url, **kwargs)
  File "C:\Users\E1002312\AppData\Local\Programs\Python\Python310\lib\site-packages\requests\sessions.py", line 587, in request
    resp = self.send(prep, **send_kwargs)
  File "C:\Users\E1002312\AppData\Local\Programs\Python\Python310\lib\site-packages\requests\sessions.py", line 701, in send
    r = adapter.send(request, **kwargs)
  File "C:\Users\E1002312\AppData\Local\Programs\Python\Python310\lib\site-packages\requests\adapters.py", line 563, in send
    raise SSLError(e, request=request)
requests.exceptions.SSLError: HTTPSConnectionPool(host='en.wikipedia.org', port=443): Max retries exceeded with url: /w/api.php?action=query&format=json&list=search&srsearch=mom (Caused by SSLError(SSLCertVerificationError(1, '[SSL: CERTIFICATE_VERIFY_FAILED] certificate verify failed: unable to get local issuer certificate (_ssl.c:997)')))
2023-03-14 11:28:14,268 INFO 127.0.0.1 - - [14/Mar/2023 11:28:14] "[35m[1mGET /?q=mom HTTP/1.1[0m" 500 -
2023-03-14 11:28:14,374 INFO 127.0.0.1 - - [14/Mar/2023 11:28:14] "[36mGET /?__debugger__=yes&cmd=resource&f=style.css HTTP/1.1[0m" 304 -
2023-03-14 11:28:14,376 INFO 127.0.0.1 - - [14/Mar/2023 11:28:14] "[36mGET /?__debugger__=yes&cmd=resource&f=debugger.js HTTP/1.1[0m" 304 -
2023-03-14 11:28:14,413 INFO 127.0.0.1 - - [14/Mar/2023 11:28:14] "[36mGET /?__debugger__=yes&cmd=resource&f=console.png HTTP/1.1[0m" 304 -
2023-03-14 12:01:43,471 DEBUG Starting new HTTPS connection (1): en.wikipedia.org:443
2023-03-14 12:01:45,164 DEBUG https://en.wikipedia.org:443 "GET /w/api.php HTTP/1.1" 200 None
2023-03-14 12:01:45,201 INFO [31m[1mWARNING: This is a development server. Do not use it in a production deployment. Use a production WSGI server instead.[0m
 * Running on http://127.0.0.1:5000
2023-03-14 12:01:45,202 INFO [33mPress CTRL+C to quit[0m
2023-03-14 12:01:45,205 INFO  * Restarting with stat
2023-03-14 12:01:47,163 DEBUG Starting new HTTPS connection (1): en.wikipedia.org:443
2023-03-14 12:01:48,873 DEBUG https://en.wikipedia.org:443 "GET /w/api.php HTTP/1.1" 200 None
2023-03-14 12:01:48,907 WARNING  * Debugger is active!
2023-03-14 12:01:48,917 INFO  * Debugger PIN: 220-726-321
2023-03-14 12:02:49,657 INFO No data in query, wiki.html has loaded
2023-03-14 12:02:49,683 INFO 127.0.0.1 - - [14/Mar/2023 12:02:49] "GET / HTTP/1.1" 200 -
2023-03-14 12:02:56,217 DEBUG Starting new HTTPS connection (1): en.wikipedia.org:443
2023-03-14 12:02:57,118 ERROR issues loading the data HTTPSConnectionPool(host='en.wikipedia.org', port=443): Max retries exceeded with url: /w/api.php?action=query&format=json&list=search&srsearch=goog (Caused by SSLError(SSLCertVerificationError(1, '[SSL: CERTIFICATE_VERIFY_FAILED] certificate verify failed: unable to get local issuer certificate (_ssl.c:997)')))
Traceback (most recent call last):
  File "C:\Users\E1002312\AppData\Local\Programs\Python\Python310\lib\site-packages\urllib3\connectionpool.py", line 703, in urlopen
    httplib_response = self._make_request(
  File "C:\Users\E1002312\AppData\Local\Programs\Python\Python310\lib\site-packages\urllib3\connectionpool.py", line 386, in _make_request
    self._validate_conn(conn)
  File "C:\Users\E1002312\AppData\Local\Programs\Python\Python310\lib\site-packages\urllib3\connectionpool.py", line 1042, in _validate_conn
    conn.connect()
  File "C:\Users\E1002312\AppData\Local\Programs\Python\Python310\lib\site-packages\urllib3\connection.py", line 419, in connect
    self.sock = ssl_wrap_socket(
  File "C:\Users\E1002312\AppData\Local\Programs\Python\Python310\lib\site-packages\urllib3\util\ssl_.py", line 449, in ssl_wrap_socket
    ssl_sock = _ssl_wrap_socket_impl(
  File "C:\Users\E1002312\AppData\Local\Programs\Python\Python310\lib\site-packages\urllib3\util\ssl_.py", line 493, in _ssl_wrap_socket_impl
    return ssl_context.wrap_socket(sock, server_hostname=server_hostname)
  File "C:\Users\E1002312\AppData\Local\Programs\Python\Python310\lib\ssl.py", line 513, in wrap_socket
    return self.sslsocket_class._create(
  File "C:\Users\E1002312\AppData\Local\Programs\Python\Python310\lib\ssl.py", line 1071, in _create
    self.do_handshake()
  File "C:\Users\E1002312\AppData\Local\Programs\Python\Python310\lib\ssl.py", line 1342, in do_handshake
    self._sslobj.do_handshake()
ssl.SSLCertVerificationError: [SSL: CERTIFICATE_VERIFY_FAILED] certificate verify failed: unable to get local issuer certificate (_ssl.c:997)

During handling of the above exception, another exception occurred:

Traceback (most recent call last):
  File "C:\Users\E1002312\AppData\Local\Programs\Python\Python310\lib\site-packages\requests\adapters.py", line 489, in send
    resp = conn.urlopen(
  File "C:\Users\E1002312\AppData\Local\Programs\Python\Python310\lib\site-packages\urllib3\connectionpool.py", line 787, in urlopen
    retries = retries.increment(
  File "C:\Users\E1002312\AppData\Local\Programs\Python\Python310\lib\site-packages\urllib3\util\retry.py", line 592, in increment
    raise MaxRetryError(_pool, url, error or ResponseError(cause))
urllib3.exceptions.MaxRetryError: HTTPSConnectionPool(host='en.wikipedia.org', port=443): Max retries exceeded with url: /w/api.php?action=query&format=json&list=search&srsearch=goog (Caused by SSLError(SSLCertVerificationError(1, '[SSL: CERTIFICATE_VERIFY_FAILED] certificate verify failed: unable to get local issuer certificate (_ssl.c:997)')))

During handling of the above exception, another exception occurred:

Traceback (most recent call last):
  File "C:\Users\E1002312\OneDrive - Sanlam Life Insurance Limited\Desktop\SM Khama\Python-Flask\app.py", line 25, in home
    data = requests.get(URL,params={'action': 'query', 'format': 'json', 'list': 'search', 'srsearch': request.args.get('q')})
  File "C:\Users\E1002312\AppData\Local\Programs\Python\Python310\lib\site-packages\requests\api.py", line 73, in get
    return request("get", url, params=params, **kwargs)
  File "C:\Users\E1002312\AppData\Local\Programs\Python\Python310\lib\site-packages\requests\api.py", line 59, in request
    return session.request(method=method, url=url, **kwargs)
  File "C:\Users\E1002312\AppData\Local\Programs\Python\Python310\lib\site-packages\requests\sessions.py", line 587, in request
    resp = self.send(prep, **send_kwargs)
  File "C:\Users\E1002312\AppData\Local\Programs\Python\Python310\lib\site-packages\requests\sessions.py", line 701, in send
    r = adapter.send(request, **kwargs)
  File "C:\Users\E1002312\AppData\Local\Programs\Python\Python310\lib\site-packages\requests\adapters.py", line 563, in send
    raise SSLError(e, request=request)
requests.exceptions.SSLError: HTTPSConnectionPool(host='en.wikipedia.org', port=443): Max retries exceeded with url: /w/api.php?action=query&format=json&list=search&srsearch=goog (Caused by SSLError(SSLCertVerificationError(1, '[SSL: CERTIFICATE_VERIFY_FAILED] certificate verify failed: unable to get local issuer certificate (_ssl.c:997)')))
2023-03-14 12:02:57,181 INFO 127.0.0.1 - - [14/Mar/2023 12:02:57] "[35m[1mGET /?q=goog HTTP/1.1[0m" 500 -
2023-03-14 12:02:57,314 INFO 127.0.0.1 - - [14/Mar/2023 12:02:57] "[36mGET /?__debugger__=yes&cmd=resource&f=style.css HTTP/1.1[0m" 304 -
2023-03-14 12:02:57,317 INFO 127.0.0.1 - - [14/Mar/2023 12:02:57] "[36mGET /?__debugger__=yes&cmd=resource&f=debugger.js HTTP/1.1[0m" 304 -
2023-03-14 12:02:57,372 INFO 127.0.0.1 - - [14/Mar/2023 12:02:57] "[36mGET /?__debugger__=yes&cmd=resource&f=console.png HTTP/1.1[0m" 304 -
2023-03-15 09:46:51,147 DEBUG Starting new HTTPS connection (1): en.wikipedia.org:443
2023-03-15 09:46:53,176 DEBUG https://en.wikipedia.org:443 "GET /w/api.php HTTP/1.1" 200 None
2023-03-15 09:46:53,209 INFO [31m[1mWARNING: This is a development server. Do not use it in a production deployment. Use a production WSGI server instead.[0m
 * Running on http://127.0.0.1:5000
2023-03-15 09:46:53,210 INFO [33mPress CTRL+C to quit[0m
2023-03-15 09:46:53,217 INFO  * Restarting with stat
2023-03-15 09:46:54,541 DEBUG Starting new HTTPS connection (1): en.wikipedia.org:443
2023-03-15 09:46:56,434 DEBUG https://en.wikipedia.org:443 "GET /w/api.php HTTP/1.1" 200 None
2023-03-15 09:46:56,454 WARNING  * Debugger is active!
2023-03-15 09:46:56,461 INFO  * Debugger PIN: 220-726-321
2023-03-15 09:47:10,528 INFO No data in query, wiki.html has loaded
2023-03-15 09:47:10,543 INFO 127.0.0.1 - - [15/Mar/2023 09:47:10] "GET / HTTP/1.1" 200 -
2023-03-15 09:47:16,323 DEBUG Starting new HTTPS connection (1): en.wikipedia.org:443
2023-03-15 09:47:16,763 ERROR issues loading the data HTTPSConnectionPool(host='en.wikipedia.org', port=443): Max retries exceeded with url: /w/api.php?action=query&format=json&list=search&srsearch=one (Caused by SSLError(SSLCertVerificationError(1, '[SSL: CERTIFICATE_VERIFY_FAILED] certificate verify failed: unable to get local issuer certificate (_ssl.c:997)')))
Traceback (most recent call last):
  File "C:\Users\E1002312\AppData\Local\Programs\Python\Python310\lib\site-packages\urllib3\connectionpool.py", line 703, in urlopen
    httplib_response = self._make_request(
  File "C:\Users\E1002312\AppData\Local\Programs\Python\Python310\lib\site-packages\urllib3\connectionpool.py", line 386, in _make_request
    self._validate_conn(conn)
  File "C:\Users\E1002312\AppData\Local\Programs\Python\Python310\lib\site-packages\urllib3\connectionpool.py", line 1042, in _validate_conn
    conn.connect()
  File "C:\Users\E1002312\AppData\Local\Programs\Python\Python310\lib\site-packages\urllib3\connection.py", line 419, in connect
    self.sock = ssl_wrap_socket(
  File "C:\Users\E1002312\AppData\Local\Programs\Python\Python310\lib\site-packages\urllib3\util\ssl_.py", line 449, in ssl_wrap_socket
    ssl_sock = _ssl_wrap_socket_impl(
  File "C:\Users\E1002312\AppData\Local\Programs\Python\Python310\lib\site-packages\urllib3\util\ssl_.py", line 493, in _ssl_wrap_socket_impl
    return ssl_context.wrap_socket(sock, server_hostname=server_hostname)
  File "C:\Users\E1002312\AppData\Local\Programs\Python\Python310\lib\ssl.py", line 513, in wrap_socket
    return self.sslsocket_class._create(
  File "C:\Users\E1002312\AppData\Local\Programs\Python\Python310\lib\ssl.py", line 1071, in _create
    self.do_handshake()
  File "C:\Users\E1002312\AppData\Local\Programs\Python\Python310\lib\ssl.py", line 1342, in do_handshake
    self._sslobj.do_handshake()
ssl.SSLCertVerificationError: [SSL: CERTIFICATE_VERIFY_FAILED] certificate verify failed: unable to get local issuer certificate (_ssl.c:997)

During handling of the above exception, another exception occurred:

Traceback (most recent call last):
  File "C:\Users\E1002312\AppData\Local\Programs\Python\Python310\lib\site-packages\requests\adapters.py", line 489, in send
    resp = conn.urlopen(
  File "C:\Users\E1002312\AppData\Local\Programs\Python\Python310\lib\site-packages\urllib3\connectionpool.py", line 787, in urlopen
    retries = retries.increment(
  File "C:\Users\E1002312\AppData\Local\Programs\Python\Python310\lib\site-packages\urllib3\util\retry.py", line 592, in increment
    raise MaxRetryError(_pool, url, error or ResponseError(cause))
urllib3.exceptions.MaxRetryError: HTTPSConnectionPool(host='en.wikipedia.org', port=443): Max retries exceeded with url: /w/api.php?action=query&format=json&list=search&srsearch=one (Caused by SSLError(SSLCertVerificationError(1, '[SSL: CERTIFICATE_VERIFY_FAILED] certificate verify failed: unable to get local issuer certificate (_ssl.c:997)')))

During handling of the above exception, another exception occurred:

Traceback (most recent call last):
  File "C:\Users\E1002312\OneDrive - Sanlam Life Insurance Limited\Desktop\SM Khama\Python-Flask\app.py", line 27, in home
    data = requests.get(URL,params={'action': 'query', 'format': 'json', 'list': 'search', 'srsearch': request.args.get('q')})
  File "C:\Users\E1002312\AppData\Local\Programs\Python\Python310\lib\site-packages\requests\api.py", line 73, in get
    return request("get", url, params=params, **kwargs)
  File "C:\Users\E1002312\AppData\Local\Programs\Python\Python310\lib\site-packages\requests\api.py", line 59, in request
    return session.request(method=method, url=url, **kwargs)
  File "C:\Users\E1002312\AppData\Local\Programs\Python\Python310\lib\site-packages\requests\sessions.py", line 587, in request
    resp = self.send(prep, **send_kwargs)
  File "C:\Users\E1002312\AppData\Local\Programs\Python\Python310\lib\site-packages\requests\sessions.py", line 701, in send
    r = adapter.send(request, **kwargs)
  File "C:\Users\E1002312\AppData\Local\Programs\Python\Python310\lib\site-packages\requests\adapters.py", line 563, in send
    raise SSLError(e, request=request)
requests.exceptions.SSLError: HTTPSConnectionPool(host='en.wikipedia.org', port=443): Max retries exceeded with url: /w/api.php?action=query&format=json&list=search&srsearch=one (Caused by SSLError(SSLCertVerificationError(1, '[SSL: CERTIFICATE_VERIFY_FAILED] certificate verify failed: unable to get local issuer certificate (_ssl.c:997)')))
2023-03-15 09:47:16,807 INFO 127.0.0.1 - - [15/Mar/2023 09:47:16] "[35m[1mGET /?q=one HTTP/1.1[0m" 500 -
2023-03-15 09:47:16,924 INFO 127.0.0.1 - - [15/Mar/2023 09:47:16] "[36mGET /?__debugger__=yes&cmd=resource&f=debugger.js HTTP/1.1[0m" 304 -
2023-03-15 09:47:16,925 INFO 127.0.0.1 - - [15/Mar/2023 09:47:16] "[36mGET /?__debugger__=yes&cmd=resource&f=style.css HTTP/1.1[0m" 304 -
2023-03-15 09:47:16,954 INFO 127.0.0.1 - - [15/Mar/2023 09:47:16] "[36mGET /?__debugger__=yes&cmd=resource&f=console.png HTTP/1.1[0m" 304 -
2023-03-15 10:43:14,834 DEBUG Starting new HTTPS connection (1): en.wikipedia.org:443
2023-03-15 10:43:16,878 DEBUG https://en.wikipedia.org:443 "GET /w/api.php HTTP/1.1" 200 None
2023-03-15 10:43:16,902 INFO [31m[1mWARNING: This is a development server. Do not use it in a production deployment. Use a production WSGI server instead.[0m
 * Running on http://127.0.0.1:5000
2023-03-15 10:43:16,902 INFO [33mPress CTRL+C to quit[0m
2023-03-15 10:43:16,905 INFO  * Restarting with stat
2023-03-15 10:43:17,863 DEBUG Starting new HTTPS connection (1): en.wikipedia.org:443
2023-03-15 10:43:19,431 DEBUG https://en.wikipedia.org:443 "GET /w/api.php HTTP/1.1" 200 None
2023-03-15 10:43:19,442 WARNING  * Debugger is active!
2023-03-15 10:43:19,446 INFO  * Debugger PIN: 220-726-321
2023-03-15 10:43:33,613 INFO No data in query, wiki.html has loaded
2023-03-15 10:43:33,640 ERROR issues loading the data Could not build url for endpoint ' static' with values ['filename']. Did you mean 'static' instead?
Traceback (most recent call last):
  File "C:\Users\E1002312\OneDrive - Sanlam Life Insurance Limited\Desktop\SM Khama\Python-Flask\app.py", line 25, in home
    return render_template('wiki.html')
  File "C:\Users\E1002312\AppData\Local\Programs\Python\Python310\lib\site-packages\flask\templating.py", line 147, in render_template
    return _render(app, template, context)
  File "C:\Users\E1002312\AppData\Local\Programs\Python\Python310\lib\site-packages\flask\templating.py", line 130, in _render
    rv = template.render(context)
  File "C:\Users\E1002312\AppData\Local\Programs\Python\Python310\lib\site-packages\jinja2\environment.py", line 1301, in render
    self.environment.handle_exception()
  File "C:\Users\E1002312\AppData\Local\Programs\Python\Python310\lib\site-packages\jinja2\environment.py", line 936, in handle_exception
    raise rewrite_traceback_stack(source=source)
  File "C:\Users\E1002312\OneDrive - Sanlam Life Insurance Limited\Desktop\SM Khama\Python-Flask\templates\wiki.html", line 8, in top-level template code
    <link rel="stylesheet" href="{{url_for(" static", filename="style.css" )}}">
  File "C:\Users\E1002312\AppData\Local\Programs\Python\Python310\lib\site-packages\flask\app.py", line 2034, in url_for
    return self.handle_url_build_error(error, endpoint, values)
  File "C:\Users\E1002312\AppData\Local\Programs\Python\Python310\lib\site-packages\flask\app.py", line 2023, in url_for
    rv = url_adapter.build(  # type: ignore[union-attr]
  File "C:\Users\E1002312\AppData\Local\Programs\Python\Python310\lib\site-packages\werkzeug\routing\map.py", line 917, in build
    raise BuildError(endpoint, values, method, self)
werkzeug.routing.exceptions.BuildError: Could not build url for endpoint ' static' with values ['filename']. Did you mean 'static' instead?
2023-03-15 10:43:33,684 INFO 127.0.0.1 - - [15/Mar/2023 10:43:33] "[35m[1mGET / HTTP/1.1[0m" 500 -
2023-03-15 10:43:33,828 INFO 127.0.0.1 - - [15/Mar/2023 10:43:33] "[36mGET /?__debugger__=yes&cmd=resource&f=debugger.js HTTP/1.1[0m" 304 -
2023-03-15 10:43:33,829 INFO 127.0.0.1 - - [15/Mar/2023 10:43:33] "[36mGET /?__debugger__=yes&cmd=resource&f=style.css HTTP/1.1[0m" 304 -
2023-03-15 10:43:33,888 INFO 127.0.0.1 - - [15/Mar/2023 10:43:33] "[36mGET /?__debugger__=yes&cmd=resource&f=console.png HTTP/1.1[0m" 304 -
2023-03-15 10:43:38,591 INFO No data in query, wiki.html has loaded
2023-03-15 10:43:38,594 ERROR issues loading the data Could not build url for endpoint ' static' with values ['filename']. Did you mean 'static' instead?
Traceback (most recent call last):
  File "C:\Users\E1002312\OneDrive - Sanlam Life Insurance Limited\Desktop\SM Khama\Python-Flask\app.py", line 25, in home
    return render_template('wiki.html')
  File "C:\Users\E1002312\AppData\Local\Programs\Python\Python310\lib\site-packages\flask\templating.py", line 147, in render_template
    return _render(app, template, context)
  File "C:\Users\E1002312\AppData\Local\Programs\Python\Python310\lib\site-packages\flask\templating.py", line 130, in _render
    rv = template.render(context)
  File "C:\Users\E1002312\AppData\Local\Programs\Python\Python310\lib\site-packages\jinja2\environment.py", line 1301, in render
    self.environment.handle_exception()
  File "C:\Users\E1002312\AppData\Local\Programs\Python\Python310\lib\site-packages\jinja2\environment.py", line 936, in handle_exception
    raise rewrite_traceback_stack(source=source)
  File "C:\Users\E1002312\OneDrive - Sanlam Life Insurance Limited\Desktop\SM Khama\Python-Flask\templates\wiki.html", line 8, in top-level template code
    <link rel="stylesheet" href="{{url_for(" static", filename="style.css" )}}">
  File "C:\Users\E1002312\AppData\Local\Programs\Python\Python310\lib\site-packages\flask\app.py", line 2034, in url_for
    return self.handle_url_build_error(error, endpoint, values)
  File "C:\Users\E1002312\AppData\Local\Programs\Python\Python310\lib\site-packages\flask\app.py", line 2023, in url_for
    rv = url_adapter.build(  # type: ignore[union-attr]
  File "C:\Users\E1002312\AppData\Local\Programs\Python\Python310\lib\site-packages\werkzeug\routing\map.py", line 917, in build
    raise BuildError(endpoint, values, method, self)
werkzeug.routing.exceptions.BuildError: Could not build url for endpoint ' static' with values ['filename']. Did you mean 'static' instead?
2023-03-15 10:43:38,620 INFO 127.0.0.1 - - [15/Mar/2023 10:43:38] "[35m[1mGET / HTTP/1.1[0m" 500 -
2023-03-15 10:43:38,662 INFO 127.0.0.1 - - [15/Mar/2023 10:43:38] "[36mGET /?__debugger__=yes&cmd=resource&f=style.css HTTP/1.1[0m" 304 -
2023-03-15 10:43:38,671 INFO 127.0.0.1 - - [15/Mar/2023 10:43:38] "[36mGET /?__debugger__=yes&cmd=resource&f=debugger.js HTTP/1.1[0m" 304 -
2023-03-15 10:43:38,689 INFO 127.0.0.1 - - [15/Mar/2023 10:43:38] "[36mGET /?__debugger__=yes&cmd=resource&f=console.png HTTP/1.1[0m" 304 -
2023-03-15 10:43:38,716 INFO 127.0.0.1 - - [15/Mar/2023 10:43:38] "[36mGET /?__debugger__=yes&cmd=resource&f=console.png HTTP/1.1[0m" 304 -
2023-03-15 10:43:44,726 INFO No data in query, wiki.html has loaded
2023-03-15 10:43:44,727 ERROR issues loading the data Could not build url for endpoint ' static' with values ['filename']. Did you mean 'static' instead?
Traceback (most recent call last):
  File "C:\Users\E1002312\OneDrive - Sanlam Life Insurance Limited\Desktop\SM Khama\Python-Flask\app.py", line 25, in home
    return render_template('wiki.html')
  File "C:\Users\E1002312\AppData\Local\Programs\Python\Python310\lib\site-packages\flask\templating.py", line 147, in render_template
    return _render(app, template, context)
  File "C:\Users\E1002312\AppData\Local\Programs\Python\Python310\lib\site-packages\flask\templating.py", line 130, in _render
    rv = template.render(context)
  File "C:\Users\E1002312\AppData\Local\Programs\Python\Python310\lib\site-packages\jinja2\environment.py", line 1301, in render
    self.environment.handle_exception()
  File "C:\Users\E1002312\AppData\Local\Programs\Python\Python310\lib\site-packages\jinja2\environment.py", line 936, in handle_exception
    raise rewrite_traceback_stack(source=source)
  File "C:\Users\E1002312\OneDrive - Sanlam Life Insurance Limited\Desktop\SM Khama\Python-Flask\templates\wiki.html", line 8, in top-level template code
    <link rel="stylesheet" href="{{url_for(" static", filename="style.css" )}}">
  File "C:\Users\E1002312\AppData\Local\Programs\Python\Python310\lib\site-packages\flask\app.py", line 2034, in url_for
    return self.handle_url_build_error(error, endpoint, values)
  File "C:\Users\E1002312\AppData\Local\Programs\Python\Python310\lib\site-packages\flask\app.py", line 2023, in url_for
    rv = url_adapter.build(  # type: ignore[union-attr]
  File "C:\Users\E1002312\AppData\Local\Programs\Python\Python310\lib\site-packages\werkzeug\routing\map.py", line 917, in build
    raise BuildError(endpoint, values, method, self)
werkzeug.routing.exceptions.BuildError: Could not build url for endpoint ' static' with values ['filename']. Did you mean 'static' instead?
2023-03-15 10:43:44,765 INFO 127.0.0.1 - - [15/Mar/2023 10:43:44] "[35m[1mGET / HTTP/1.1[0m" 500 -
2023-03-15 10:43:44,793 INFO 127.0.0.1 - - [15/Mar/2023 10:43:44] "[36mGET /?__debugger__=yes&cmd=resource&f=style.css HTTP/1.1[0m" 304 -
2023-03-15 10:43:44,814 INFO 127.0.0.1 - - [15/Mar/2023 10:43:44] "[36mGET /?__debugger__=yes&cmd=resource&f=debugger.js HTTP/1.1[0m" 304 -
2023-03-15 10:43:44,882 INFO 127.0.0.1 - - [15/Mar/2023 10:43:44] "[36mGET /?__debugger__=yes&cmd=resource&f=console.png HTTP/1.1[0m" 304 -
2023-03-15 10:43:50,570 INFO No data in query, wiki.html has loaded
2023-03-15 10:43:50,571 ERROR issues loading the data Could not build url for endpoint ' static' with values ['filename']. Did you mean 'static' instead?
Traceback (most recent call last):
  File "C:\Users\E1002312\OneDrive - Sanlam Life Insurance Limited\Desktop\SM Khama\Python-Flask\app.py", line 25, in home
    return render_template('wiki.html')
  File "C:\Users\E1002312\AppData\Local\Programs\Python\Python310\lib\site-packages\flask\templating.py", line 147, in render_template
    return _render(app, template, context)
  File "C:\Users\E1002312\AppData\Local\Programs\Python\Python310\lib\site-packages\flask\templating.py", line 130, in _render
    rv = template.render(context)
  File "C:\Users\E1002312\AppData\Local\Programs\Python\Python310\lib\site-packages\jinja2\environment.py", line 1301, in render
    self.environment.handle_exception()
  File "C:\Users\E1002312\AppData\Local\Programs\Python\Python310\lib\site-packages\jinja2\environment.py", line 936, in handle_exception
    raise rewrite_traceback_stack(source=source)
  File "C:\Users\E1002312\OneDrive - Sanlam Life Insurance Limited\Desktop\SM Khama\Python-Flask\templates\wiki.html", line 8, in top-level template code
    <link rel="stylesheet" href="{{url_for(" static", filename="style.css" )}}">
  File "C:\Users\E1002312\AppData\Local\Programs\Python\Python310\lib\site-packages\flask\app.py", line 2034, in url_for
    return self.handle_url_build_error(error, endpoint, values)
  File "C:\Users\E1002312\AppData\Local\Programs\Python\Python310\lib\site-packages\flask\app.py", line 2023, in url_for
    rv = url_adapter.build(  # type: ignore[union-attr]
  File "C:\Users\E1002312\AppData\Local\Programs\Python\Python310\lib\site-packages\werkzeug\routing\map.py", line 917, in build
    raise BuildError(endpoint, values, method, self)
werkzeug.routing.exceptions.BuildError: Could not build url for endpoint ' static' with values ['filename']. Did you mean 'static' instead?
2023-03-15 10:43:50,596 INFO 127.0.0.1 - - [15/Mar/2023 10:43:50] "[35m[1mGET / HTTP/1.1[0m" 500 -
2023-03-15 10:43:50,645 INFO 127.0.0.1 - - [15/Mar/2023 10:43:50] "[36mGET /?__debugger__=yes&cmd=resource&f=style.css HTTP/1.1[0m" 304 -
2023-03-15 10:43:50,679 INFO 127.0.0.1 - - [15/Mar/2023 10:43:50] "[36mGET /?__debugger__=yes&cmd=resource&f=debugger.js HTTP/1.1[0m" 304 -
2023-03-15 10:43:50,694 INFO 127.0.0.1 - - [15/Mar/2023 10:43:50] "[36mGET /?__debugger__=yes&cmd=resource&f=console.png HTTP/1.1[0m" 304 -
2023-03-15 10:43:50,719 INFO 127.0.0.1 - - [15/Mar/2023 10:43:50] "[36mGET /?__debugger__=yes&cmd=resource&f=console.png HTTP/1.1[0m" 304 -
2023-03-15 10:43:53,620 INFO No data in query, wiki.html has loaded
2023-03-15 10:43:53,622 ERROR issues loading the data Could not build url for endpoint ' static' with values ['filename']. Did you mean 'static' instead?
Traceback (most recent call last):
  File "C:\Users\E1002312\OneDrive - Sanlam Life Insurance Limited\Desktop\SM Khama\Python-Flask\app.py", line 25, in home
    return render_template('wiki.html')
  File "C:\Users\E1002312\AppData\Local\Programs\Python\Python310\lib\site-packages\flask\templating.py", line 147, in render_template
    return _render(app, template, context)
  File "C:\Users\E1002312\AppData\Local\Programs\Python\Python310\lib\site-packages\flask\templating.py", line 130, in _render
    rv = template.render(context)
  File "C:\Users\E1002312\AppData\Local\Programs\Python\Python310\lib\site-packages\jinja2\environment.py", line 1301, in render
    self.environment.handle_exception()
  File "C:\Users\E1002312\AppData\Local\Programs\Python\Python310\lib\site-packages\jinja2\environment.py", line 936, in handle_exception
    raise rewrite_traceback_stack(source=source)
  File "C:\Users\E1002312\OneDrive - Sanlam Life Insurance Limited\Desktop\SM Khama\Python-Flask\templates\wiki.html", line 8, in top-level template code
    <link rel="stylesheet" href="{{url_for(" static", filename="style.css" )}}">
  File "C:\Users\E1002312\AppData\Local\Programs\Python\Python310\lib\site-packages\flask\app.py", line 2034, in url_for
    return self.handle_url_build_error(error, endpoint, values)
  File "C:\Users\E1002312\AppData\Local\Programs\Python\Python310\lib\site-packages\flask\app.py", line 2023, in url_for
    rv = url_adapter.build(  # type: ignore[union-attr]
  File "C:\Users\E1002312\AppData\Local\Programs\Python\Python310\lib\site-packages\werkzeug\routing\map.py", line 917, in build
    raise BuildError(endpoint, values, method, self)
werkzeug.routing.exceptions.BuildError: Could not build url for endpoint ' static' with values ['filename']. Did you mean 'static' instead?
2023-03-15 10:43:53,647 INFO 127.0.0.1 - - [15/Mar/2023 10:43:53] "[35m[1mGET / HTTP/1.1[0m" 500 -
2023-03-15 10:43:53,677 INFO 127.0.0.1 - - [15/Mar/2023 10:43:53] "[36mGET /?__debugger__=yes&cmd=resource&f=style.css HTTP/1.1[0m" 304 -
2023-03-15 10:43:53,682 INFO 127.0.0.1 - - [15/Mar/2023 10:43:53] "[36mGET /?__debugger__=yes&cmd=resource&f=debugger.js HTTP/1.1[0m" 304 -
2023-03-15 10:43:53,699 INFO 127.0.0.1 - - [15/Mar/2023 10:43:53] "[36mGET /?__debugger__=yes&cmd=resource&f=console.png HTTP/1.1[0m" 304 -
2023-03-15 10:43:53,721 INFO 127.0.0.1 - - [15/Mar/2023 10:43:53] "[36mGET /?__debugger__=yes&cmd=resource&f=console.png HTTP/1.1[0m" 304 -
2023-03-15 10:44:04,291 INFO No data in query, wiki.html has loaded
2023-03-15 10:44:04,294 ERROR issues loading the data Could not build url for endpoint ' static' with values ['filename']. Did you mean 'static' instead?
Traceback (most recent call last):
  File "C:\Users\E1002312\OneDrive - Sanlam Life Insurance Limited\Desktop\SM Khama\Python-Flask\app.py", line 25, in home
    return render_template('wiki.html')
  File "C:\Users\E1002312\AppData\Local\Programs\Python\Python310\lib\site-packages\flask\templating.py", line 147, in render_template
    return _render(app, template, context)
  File "C:\Users\E1002312\AppData\Local\Programs\Python\Python310\lib\site-packages\flask\templating.py", line 130, in _render
    rv = template.render(context)
  File "C:\Users\E1002312\AppData\Local\Programs\Python\Python310\lib\site-packages\jinja2\environment.py", line 1301, in render
    self.environment.handle_exception()
  File "C:\Users\E1002312\AppData\Local\Programs\Python\Python310\lib\site-packages\jinja2\environment.py", line 936, in handle_exception
    raise rewrite_traceback_stack(source=source)
  File "C:\Users\E1002312\OneDrive - Sanlam Life Insurance Limited\Desktop\SM Khama\Python-Flask\templates\wiki.html", line 8, in top-level template code
    <link rel="stylesheet" href="{{url_for(" static", filename="style.css" )}}">
  File "C:\Users\E1002312\AppData\Local\Programs\Python\Python310\lib\site-packages\flask\app.py", line 2034, in url_for
    return self.handle_url_build_error(error, endpoint, values)
  File "C:\Users\E1002312\AppData\Local\Programs\Python\Python310\lib\site-packages\flask\app.py", line 2023, in url_for
    rv = url_adapter.build(  # type: ignore[union-attr]
  File "C:\Users\E1002312\AppData\Local\Programs\Python\Python310\lib\site-packages\werkzeug\routing\map.py", line 917, in build
    raise BuildError(endpoint, values, method, self)
werkzeug.routing.exceptions.BuildError: Could not build url for endpoint ' static' with values ['filename']. Did you mean 'static' instead?
2023-03-15 10:44:04,334 INFO 127.0.0.1 - - [15/Mar/2023 10:44:04] "[35m[1mGET / HTTP/1.1[0m" 500 -
2023-03-15 10:44:04,379 INFO 127.0.0.1 - - [15/Mar/2023 10:44:04] "[36mGET /?__debugger__=yes&cmd=resource&f=style.css HTTP/1.1[0m" 304 -
2023-03-15 10:44:04,411 INFO 127.0.0.1 - - [15/Mar/2023 10:44:04] "[36mGET /?__debugger__=yes&cmd=resource&f=debugger.js HTTP/1.1[0m" 304 -
2023-03-15 10:44:04,489 INFO 127.0.0.1 - - [15/Mar/2023 10:44:04] "[36mGET /?__debugger__=yes&cmd=resource&f=console.png HTTP/1.1[0m" 304 -
2023-03-15 10:44:38,840 DEBUG Starting new HTTPS connection (1): en.wikipedia.org:443
2023-03-15 10:44:40,724 DEBUG https://en.wikipedia.org:443 "GET /w/api.php HTTP/1.1" 200 None
2023-03-15 10:44:40,753 INFO [31m[1mWARNING: This is a development server. Do not use it in a production deployment. Use a production WSGI server instead.[0m
 * Running on http://127.0.0.1:5000
2023-03-15 10:44:40,754 INFO [33mPress CTRL+C to quit[0m
2023-03-15 10:44:40,759 INFO  * Restarting with stat
2023-03-15 10:44:41,824 DEBUG Starting new HTTPS connection (1): en.wikipedia.org:443
2023-03-15 10:44:43,386 DEBUG https://en.wikipedia.org:443 "GET /w/api.php HTTP/1.1" 200 None
2023-03-15 10:44:43,397 WARNING  * Debugger is active!
2023-03-15 10:44:43,401 INFO  * Debugger PIN: 220-726-321
2023-03-15 10:45:09,193 DEBUG Starting new HTTPS connection (1): en.wikipedia.org:443
2023-03-15 10:45:10,744 DEBUG https://en.wikipedia.org:443 "GET /w/api.php HTTP/1.1" 200 None
2023-03-15 10:45:10,768 INFO [31m[1mWARNING: This is a development server. Do not use it in a production deployment. Use a production WSGI server instead.[0m
 * Running on http://127.0.0.1:5000
2023-03-15 10:45:10,768 INFO [33mPress CTRL+C to quit[0m
2023-03-15 10:45:10,771 INFO  * Restarting with stat
2023-03-15 10:45:11,765 DEBUG Starting new HTTPS connection (1): en.wikipedia.org:443
2023-03-15 10:45:13,329 DEBUG https://en.wikipedia.org:443 "GET /w/api.php HTTP/1.1" 200 None
2023-03-15 10:45:13,342 WARNING  * Debugger is active!
2023-03-15 10:45:13,347 INFO  * Debugger PIN: 220-726-321
2023-03-15 10:45:15,306 INFO No data in query, wiki.html has loaded
2023-03-15 10:45:15,323 INFO 127.0.0.1 - - [15/Mar/2023 10:45:15] "GET / HTTP/1.1" 200 -
2023-03-15 10:45:15,425 INFO 127.0.0.1 - - [15/Mar/2023 10:45:15] "GET /static/styles.css HTTP/1.1" 200 -
2023-03-15 10:45:21,744 DEBUG Starting new HTTPS connection (1): en.wikipedia.org:443
2023-03-15 10:45:22,211 ERROR issues loading the data HTTPSConnectionPool(host='en.wikipedia.org', port=443): Max retries exceeded with url: /w/api.php?action=query&format=json&list=search&srsearch=hghg (Caused by SSLError(SSLCertVerificationError(1, '[SSL: CERTIFICATE_VERIFY_FAILED] certificate verify failed: unable to get local issuer certificate (_ssl.c:997)')))
Traceback (most recent call last):
  File "C:\Users\E1002312\AppData\Local\Programs\Python\Python310\lib\site-packages\urllib3\connectionpool.py", line 703, in urlopen
    httplib_response = self._make_request(
  File "C:\Users\E1002312\AppData\Local\Programs\Python\Python310\lib\site-packages\urllib3\connectionpool.py", line 386, in _make_request
    self._validate_conn(conn)
  File "C:\Users\E1002312\AppData\Local\Programs\Python\Python310\lib\site-packages\urllib3\connectionpool.py", line 1042, in _validate_conn
    conn.connect()
  File "C:\Users\E1002312\AppData\Local\Programs\Python\Python310\lib\site-packages\urllib3\connection.py", line 419, in connect
    self.sock = ssl_wrap_socket(
  File "C:\Users\E1002312\AppData\Local\Programs\Python\Python310\lib\site-packages\urllib3\util\ssl_.py", line 449, in ssl_wrap_socket
    ssl_sock = _ssl_wrap_socket_impl(
  File "C:\Users\E1002312\AppData\Local\Programs\Python\Python310\lib\site-packages\urllib3\util\ssl_.py", line 493, in _ssl_wrap_socket_impl
    return ssl_context.wrap_socket(sock, server_hostname=server_hostname)
  File "C:\Users\E1002312\AppData\Local\Programs\Python\Python310\lib\ssl.py", line 513, in wrap_socket
    return self.sslsocket_class._create(
  File "C:\Users\E1002312\AppData\Local\Programs\Python\Python310\lib\ssl.py", line 1071, in _create
    self.do_handshake()
  File "C:\Users\E1002312\AppData\Local\Programs\Python\Python310\lib\ssl.py", line 1342, in do_handshake
    self._sslobj.do_handshake()
ssl.SSLCertVerificationError: [SSL: CERTIFICATE_VERIFY_FAILED] certificate verify failed: unable to get local issuer certificate (_ssl.c:997)

During handling of the above exception, another exception occurred:

Traceback (most recent call last):
  File "C:\Users\E1002312\AppData\Local\Programs\Python\Python310\lib\site-packages\requests\adapters.py", line 489, in send
    resp = conn.urlopen(
  File "C:\Users\E1002312\AppData\Local\Programs\Python\Python310\lib\site-packages\urllib3\connectionpool.py", line 787, in urlopen
    retries = retries.increment(
  File "C:\Users\E1002312\AppData\Local\Programs\Python\Python310\lib\site-packages\urllib3\util\retry.py", line 592, in increment
    raise MaxRetryError(_pool, url, error or ResponseError(cause))
urllib3.exceptions.MaxRetryError: HTTPSConnectionPool(host='en.wikipedia.org', port=443): Max retries exceeded with url: /w/api.php?action=query&format=json&list=search&srsearch=hghg (Caused by SSLError(SSLCertVerificationError(1, '[SSL: CERTIFICATE_VERIFY_FAILED] certificate verify failed: unable to get local issuer certificate (_ssl.c:997)')))

During handling of the above exception, another exception occurred:

Traceback (most recent call last):
  File "C:\Users\E1002312\OneDrive - Sanlam Life Insurance Limited\Desktop\SM Khama\Python-Flask\app.py", line 27, in home
    data = requests.get(URL,params={'action': 'query', 'format': 'json', 'list': 'search', 'srsearch': request.args.get('q')})
  File "C:\Users\E1002312\AppData\Local\Programs\Python\Python310\lib\site-packages\requests\api.py", line 73, in get
    return request("get", url, params=params, **kwargs)
  File "C:\Users\E1002312\AppData\Local\Programs\Python\Python310\lib\site-packages\requests\api.py", line 59, in request
    return session.request(method=method, url=url, **kwargs)
  File "C:\Users\E1002312\AppData\Local\Programs\Python\Python310\lib\site-packages\requests\sessions.py", line 587, in request
    resp = self.send(prep, **send_kwargs)
  File "C:\Users\E1002312\AppData\Local\Programs\Python\Python310\lib\site-packages\requests\sessions.py", line 701, in send
    r = adapter.send(request, **kwargs)
  File "C:\Users\E1002312\AppData\Local\Programs\Python\Python310\lib\site-packages\requests\adapters.py", line 563, in send
    raise SSLError(e, request=request)
requests.exceptions.SSLError: HTTPSConnectionPool(host='en.wikipedia.org', port=443): Max retries exceeded with url: /w/api.php?action=query&format=json&list=search&srsearch=hghg (Caused by SSLError(SSLCertVerificationError(1, '[SSL: CERTIFICATE_VERIFY_FAILED] certificate verify failed: unable to get local issuer certificate (_ssl.c:997)')))
2023-03-15 10:45:22,255 INFO 127.0.0.1 - - [15/Mar/2023 10:45:22] "[35m[1mGET /?q=hghg HTTP/1.1[0m" 500 -
2023-03-15 10:45:22,290 INFO 127.0.0.1 - - [15/Mar/2023 10:45:22] "[36mGET /?__debugger__=yes&cmd=resource&f=style.css HTTP/1.1[0m" 304 -
2023-03-15 10:45:22,298 INFO 127.0.0.1 - - [15/Mar/2023 10:45:22] "[36mGET /?__debugger__=yes&cmd=resource&f=debugger.js HTTP/1.1[0m" 304 -
2023-03-15 10:45:22,332 INFO 127.0.0.1 - - [15/Mar/2023 10:45:22] "[36mGET /?__debugger__=yes&cmd=resource&f=console.png HTTP/1.1[0m" 304 -
2023-03-15 10:46:21,723 DEBUG Starting new HTTPS connection (1): en.wikipedia.org:443
2023-03-15 10:46:23,347 DEBUG https://en.wikipedia.org:443 "GET /w/api.php HTTP/1.1" 200 None
2023-03-15 10:46:23,375 INFO [31m[1mWARNING: This is a development server. Do not use it in a production deployment. Use a production WSGI server instead.[0m
 * Running on http://127.0.0.1:5000
2023-03-15 10:46:23,376 INFO [33mPress CTRL+C to quit[0m
2023-03-15 10:46:23,379 INFO  * Restarting with stat
2023-03-15 10:46:24,436 DEBUG Starting new HTTPS connection (1): en.wikipedia.org:443
2023-03-15 10:46:26,008 DEBUG https://en.wikipedia.org:443 "GET /w/api.php HTTP/1.1" 200 None
2023-03-15 10:46:26,022 WARNING  * Debugger is active!
2023-03-15 10:46:26,027 INFO  * Debugger PIN: 220-726-321
2023-03-15 10:46:26,060 INFO No data in query, wiki.html has loaded
2023-03-15 10:46:26,072 INFO 127.0.0.1 - - [15/Mar/2023 10:46:26] "GET / HTTP/1.1" 200 -
2023-03-15 10:46:26,146 INFO 127.0.0.1 - - [15/Mar/2023 10:46:26] "[36mGET /static/styles.css HTTP/1.1[0m" 304 -
2023-03-15 10:46:57,460 INFO No data in query, wiki.html has loaded
2023-03-15 10:46:57,467 INFO 127.0.0.1 - - [15/Mar/2023 10:46:57] "GET / HTTP/1.1" 200 -
2023-03-15 10:46:57,491 INFO 127.0.0.1 - - [15/Mar/2023 10:46:57] "[36mGET /static/styles.css HTTP/1.1[0m" 304 -
2023-03-15 10:46:58,470 INFO No data in query, wiki.html has loaded
2023-03-15 10:46:58,472 INFO 127.0.0.1 - - [15/Mar/2023 10:46:58] "GET / HTTP/1.1" 200 -
2023-03-15 10:46:58,497 INFO 127.0.0.1 - - [15/Mar/2023 10:46:58] "[36mGET /static/styles.css HTTP/1.1[0m" 304 -
2023-03-15 10:46:59,511 INFO No data in query, wiki.html has loaded
2023-03-15 10:46:59,514 INFO 127.0.0.1 - - [15/Mar/2023 10:46:59] "GET / HTTP/1.1" 200 -
2023-03-15 10:46:59,544 INFO 127.0.0.1 - - [15/Mar/2023 10:46:59] "[36mGET /static/styles.css HTTP/1.1[0m" 304 -
2023-03-15 10:47:21,772 INFO No data in query, wiki.html has loaded
2023-03-15 10:47:21,778 INFO 127.0.0.1 - - [15/Mar/2023 10:47:21] "GET / HTTP/1.1" 200 -
2023-03-15 10:47:21,803 INFO 127.0.0.1 - - [15/Mar/2023 10:47:21] "[36mGET /static/styles.css HTTP/1.1[0m" 304 -
2023-03-15 10:47:22,857 INFO No data in query, wiki.html has loaded
2023-03-15 10:47:22,858 INFO 127.0.0.1 - - [15/Mar/2023 10:47:22] "GET / HTTP/1.1" 200 -
2023-03-15 10:47:22,883 INFO 127.0.0.1 - - [15/Mar/2023 10:47:22] "[36mGET /static/styles.css HTTP/1.1[0m" 304 -
2023-03-15 10:47:23,093 INFO No data in query, wiki.html has loaded
2023-03-15 10:47:23,095 INFO 127.0.0.1 - - [15/Mar/2023 10:47:23] "GET / HTTP/1.1" 200 -
2023-03-15 10:47:23,122 INFO 127.0.0.1 - - [15/Mar/2023 10:47:23] "[36mGET /static/styles.css HTTP/1.1[0m" 304 -
2023-03-15 10:47:23,310 INFO No data in query, wiki.html has loaded
2023-03-15 10:47:23,312 INFO 127.0.0.1 - - [15/Mar/2023 10:47:23] "GET / HTTP/1.1" 200 -
2023-03-15 10:47:23,339 INFO 127.0.0.1 - - [15/Mar/2023 10:47:23] "[36mGET /static/styles.css HTTP/1.1[0m" 304 -
2023-03-15 10:47:23,529 INFO No data in query, wiki.html has loaded
2023-03-15 10:47:23,531 INFO 127.0.0.1 - - [15/Mar/2023 10:47:23] "GET / HTTP/1.1" 200 -
2023-03-15 10:47:23,559 INFO 127.0.0.1 - - [15/Mar/2023 10:47:23] "[36mGET /static/styles.css HTTP/1.1[0m" 304 -
2023-03-15 10:47:24,030 INFO No data in query, wiki.html has loaded
2023-03-15 10:47:24,031 INFO 127.0.0.1 - - [15/Mar/2023 10:47:24] "GET / HTTP/1.1" 200 -
2023-03-15 10:47:24,054 INFO 127.0.0.1 - - [15/Mar/2023 10:47:24] "[36mGET /static/styles.css HTTP/1.1[0m" 304 -
2023-03-15 10:48:24,158 DEBUG Starting new HTTPS connection (1): en.wikipedia.org:443
2023-03-15 10:48:26,093 DEBUG https://en.wikipedia.org:443 "GET /w/api.php HTTP/1.1" 200 None
2023-03-15 10:48:26,118 INFO [31m[1mWARNING: This is a development server. Do not use it in a production deployment. Use a production WSGI server instead.[0m
 * Running on http://127.0.0.1:5000
2023-03-15 10:48:26,118 INFO [33mPress CTRL+C to quit[0m
2023-03-15 10:48:26,120 INFO  * Restarting with stat
2023-03-15 10:48:27,141 DEBUG Starting new HTTPS connection (1): en.wikipedia.org:443
2023-03-15 10:48:28,667 DEBUG https://en.wikipedia.org:443 "GET /w/api.php HTTP/1.1" 200 None
2023-03-15 10:48:28,681 WARNING  * Debugger is active!
2023-03-15 10:48:28,685 INFO  * Debugger PIN: 220-726-321
2023-03-15 10:48:28,717 INFO No data in query, wiki.html has loaded
2023-03-15 10:48:28,728 INFO 127.0.0.1 - - [15/Mar/2023 10:48:28] "GET / HTTP/1.1" 200 -
2023-03-15 10:48:28,801 INFO 127.0.0.1 - - [15/Mar/2023 10:48:28] "[36mGET /static/styles.css HTTP/1.1[0m" 304 -
2023-03-15 10:54:36,788 DEBUG Starting new HTTPS connection (1): en.wikipedia.org:443
2023-03-15 10:54:38,837 DEBUG https://en.wikipedia.org:443 "GET /w/api.php HTTP/1.1" 200 None
2023-03-15 10:54:38,878 INFO [31m[1mWARNING: This is a development server. Do not use it in a production deployment. Use a production WSGI server instead.[0m
 * Running on http://127.0.0.1:5000
2023-03-15 10:54:38,878 INFO [33mPress CTRL+C to quit[0m
2023-03-15 10:54:38,884 INFO  * Restarting with stat
2023-03-15 10:54:40,393 DEBUG Starting new HTTPS connection (1): en.wikipedia.org:443
2023-03-15 10:54:41,942 DEBUG https://en.wikipedia.org:443 "GET /w/api.php HTTP/1.1" 200 None
2023-03-15 10:54:41,956 WARNING  * Debugger is active!
2023-03-15 10:54:41,960 INFO  * Debugger PIN: 220-726-321
2023-03-15 10:54:41,996 INFO No data in query, wiki.html has loaded
2023-03-15 10:54:42,009 ERROR issues loading the data Could not build url for endpoint ' static' with values ['filename']. Did you mean 'static' instead?
Traceback (most recent call last):
  File "C:\Users\E1002312\OneDrive - Sanlam Life Insurance Limited\Desktop\SM Khama\Python-Flask\app.py", line 25, in home
    return render_template('wiki.html')
  File "C:\Users\E1002312\AppData\Local\Programs\Python\Python310\lib\site-packages\flask\templating.py", line 147, in render_template
    return _render(app, template, context)
  File "C:\Users\E1002312\AppData\Local\Programs\Python\Python310\lib\site-packages\flask\templating.py", line 130, in _render
    rv = template.render(context)
  File "C:\Users\E1002312\AppData\Local\Programs\Python\Python310\lib\site-packages\jinja2\environment.py", line 1301, in render
    self.environment.handle_exception()
  File "C:\Users\E1002312\AppData\Local\Programs\Python\Python310\lib\site-packages\jinja2\environment.py", line 936, in handle_exception
    raise rewrite_traceback_stack(source=source)
  File "C:\Users\E1002312\OneDrive - Sanlam Life Insurance Limited\Desktop\SM Khama\Python-Flask\templates\wiki.html", line 8, in top-level template code
    <link rel="stylesheet" href="{{url_for(" static", filename="styles.css" )}}">
  File "C:\Users\E1002312\AppData\Local\Programs\Python\Python310\lib\site-packages\flask\app.py", line 2034, in url_for
    return self.handle_url_build_error(error, endpoint, values)
  File "C:\Users\E1002312\AppData\Local\Programs\Python\Python310\lib\site-packages\flask\app.py", line 2023, in url_for
    rv = url_adapter.build(  # type: ignore[union-attr]
  File "C:\Users\E1002312\AppData\Local\Programs\Python\Python310\lib\site-packages\werkzeug\routing\map.py", line 917, in build
    raise BuildError(endpoint, values, method, self)
werkzeug.routing.exceptions.BuildError: Could not build url for endpoint ' static' with values ['filename']. Did you mean 'static' instead?
2023-03-15 10:54:42,051 INFO 127.0.0.1 - - [15/Mar/2023 10:54:42] "[35m[1mGET / HTTP/1.1[0m" 500 -
2023-03-15 10:54:42,162 INFO 127.0.0.1 - - [15/Mar/2023 10:54:42] "[36mGET /?__debugger__=yes&cmd=resource&f=style.css HTTP/1.1[0m" 304 -
2023-03-15 10:54:42,168 INFO 127.0.0.1 - - [15/Mar/2023 10:54:42] "[36mGET /?__debugger__=yes&cmd=resource&f=debugger.js HTTP/1.1[0m" 304 -
2023-03-15 10:54:42,209 INFO 127.0.0.1 - - [15/Mar/2023 10:54:42] "[36mGET /?__debugger__=yes&cmd=resource&f=console.png HTTP/1.1[0m" 304 -
2023-03-15 10:55:02,461 DEBUG Starting new HTTPS connection (1): en.wikipedia.org:443
2023-03-15 10:55:04,007 DEBUG https://en.wikipedia.org:443 "GET /w/api.php HTTP/1.1" 200 None
2023-03-15 10:55:04,033 INFO [31m[1mWARNING: This is a development server. Do not use it in a production deployment. Use a production WSGI server instead.[0m
 * Running on http://127.0.0.1:5000
2023-03-15 10:55:04,033 INFO [33mPress CTRL+C to quit[0m
2023-03-15 10:55:04,035 INFO  * Restarting with stat
2023-03-15 10:55:05,326 DEBUG Starting new HTTPS connection (1): en.wikipedia.org:443
2023-03-15 10:55:06,947 DEBUG https://en.wikipedia.org:443 "GET /w/api.php HTTP/1.1" 200 None
2023-03-15 10:55:06,962 WARNING  * Debugger is active!
2023-03-15 10:55:06,969 INFO  * Debugger PIN: 220-726-321
2023-03-15 10:55:07,010 INFO No data in query, wiki.html has loaded
2023-03-15 10:55:07,025 INFO 127.0.0.1 - - [15/Mar/2023 10:55:07] "GET / HTTP/1.1" 200 -
2023-03-15 10:55:07,122 INFO 127.0.0.1 - - [15/Mar/2023 10:55:07] "[36mGET /static/styles.css HTTP/1.1[0m" 304 -
2023-03-15 10:56:31,593 DEBUG Starting new HTTPS connection (1): en.wikipedia.org:443
2023-03-15 10:56:33,122 DEBUG https://en.wikipedia.org:443 "GET /w/api.php HTTP/1.1" 200 None
2023-03-15 10:56:33,150 INFO [31m[1mWARNING: This is a development server. Do not use it in a production deployment. Use a production WSGI server instead.[0m
 * Running on http://127.0.0.1:5000
2023-03-15 10:56:33,151 INFO [33mPress CTRL+C to quit[0m
2023-03-15 10:56:33,153 INFO  * Restarting with stat
2023-03-15 10:56:34,194 DEBUG Starting new HTTPS connection (1): en.wikipedia.org:443
2023-03-15 10:56:35,725 DEBUG https://en.wikipedia.org:443 "GET /w/api.php HTTP/1.1" 200 None
2023-03-15 10:56:35,736 WARNING  * Debugger is active!
2023-03-15 10:56:35,740 INFO  * Debugger PIN: 220-726-321
2023-03-15 10:56:35,772 INFO No data in query, wiki.html has loaded
2023-03-15 10:56:35,783 INFO 127.0.0.1 - - [15/Mar/2023 10:56:35] "GET / HTTP/1.1" 200 -
2023-03-15 10:56:35,854 INFO 127.0.0.1 - - [15/Mar/2023 10:56:35] "[36mGET /static/styles.css HTTP/1.1[0m" 304 -
2023-03-15 10:56:52,543 DEBUG Starting new HTTPS connection (1): en.wikipedia.org:443
2023-03-15 10:56:52,990 ERROR issues loading the data HTTPSConnectionPool(host='en.wikipedia.org', port=443): Max retries exceeded with url: /w/api.php?action=query&format=json&list=search&srsearch=data (Caused by SSLError(SSLCertVerificationError(1, '[SSL: CERTIFICATE_VERIFY_FAILED] certificate verify failed: unable to get local issuer certificate (_ssl.c:997)')))
Traceback (most recent call last):
  File "C:\Users\E1002312\AppData\Local\Programs\Python\Python310\lib\site-packages\urllib3\connectionpool.py", line 703, in urlopen
    httplib_response = self._make_request(
  File "C:\Users\E1002312\AppData\Local\Programs\Python\Python310\lib\site-packages\urllib3\connectionpool.py", line 386, in _make_request
    self._validate_conn(conn)
  File "C:\Users\E1002312\AppData\Local\Programs\Python\Python310\lib\site-packages\urllib3\connectionpool.py", line 1042, in _validate_conn
    conn.connect()
  File "C:\Users\E1002312\AppData\Local\Programs\Python\Python310\lib\site-packages\urllib3\connection.py", line 419, in connect
    self.sock = ssl_wrap_socket(
  File "C:\Users\E1002312\AppData\Local\Programs\Python\Python310\lib\site-packages\urllib3\util\ssl_.py", line 449, in ssl_wrap_socket
    ssl_sock = _ssl_wrap_socket_impl(
  File "C:\Users\E1002312\AppData\Local\Programs\Python\Python310\lib\site-packages\urllib3\util\ssl_.py", line 493, in _ssl_wrap_socket_impl
    return ssl_context.wrap_socket(sock, server_hostname=server_hostname)
  File "C:\Users\E1002312\AppData\Local\Programs\Python\Python310\lib\ssl.py", line 513, in wrap_socket
    return self.sslsocket_class._create(
  File "C:\Users\E1002312\AppData\Local\Programs\Python\Python310\lib\ssl.py", line 1071, in _create
    self.do_handshake()
  File "C:\Users\E1002312\AppData\Local\Programs\Python\Python310\lib\ssl.py", line 1342, in do_handshake
    self._sslobj.do_handshake()
ssl.SSLCertVerificationError: [SSL: CERTIFICATE_VERIFY_FAILED] certificate verify failed: unable to get local issuer certificate (_ssl.c:997)

During handling of the above exception, another exception occurred:

Traceback (most recent call last):
  File "C:\Users\E1002312\AppData\Local\Programs\Python\Python310\lib\site-packages\requests\adapters.py", line 489, in send
    resp = conn.urlopen(
  File "C:\Users\E1002312\AppData\Local\Programs\Python\Python310\lib\site-packages\urllib3\connectionpool.py", line 787, in urlopen
    retries = retries.increment(
  File "C:\Users\E1002312\AppData\Local\Programs\Python\Python310\lib\site-packages\urllib3\util\retry.py", line 592, in increment
    raise MaxRetryError(_pool, url, error or ResponseError(cause))
urllib3.exceptions.MaxRetryError: HTTPSConnectionPool(host='en.wikipedia.org', port=443): Max retries exceeded with url: /w/api.php?action=query&format=json&list=search&srsearch=data (Caused by SSLError(SSLCertVerificationError(1, '[SSL: CERTIFICATE_VERIFY_FAILED] certificate verify failed: unable to get local issuer certificate (_ssl.c:997)')))

During handling of the above exception, another exception occurred:

Traceback (most recent call last):
  File "C:\Users\E1002312\OneDrive - Sanlam Life Insurance Limited\Desktop\SM Khama\Python-Flask\app.py", line 27, in home
    data = requests.get(URL,params={'action': 'query', 'format': 'json', 'list': 'search', 'srsearch': request.args.get('q')})
  File "C:\Users\E1002312\AppData\Local\Programs\Python\Python310\lib\site-packages\requests\api.py", line 73, in get
    return request("get", url, params=params, **kwargs)
  File "C:\Users\E1002312\AppData\Local\Programs\Python\Python310\lib\site-packages\requests\api.py", line 59, in request
    return session.request(method=method, url=url, **kwargs)
  File "C:\Users\E1002312\AppData\Local\Programs\Python\Python310\lib\site-packages\requests\sessions.py", line 587, in request
    resp = self.send(prep, **send_kwargs)
  File "C:\Users\E1002312\AppData\Local\Programs\Python\Python310\lib\site-packages\requests\sessions.py", line 701, in send
    r = adapter.send(request, **kwargs)
  File "C:\Users\E1002312\AppData\Local\Programs\Python\Python310\lib\site-packages\requests\adapters.py", line 563, in send
    raise SSLError(e, request=request)
requests.exceptions.SSLError: HTTPSConnectionPool(host='en.wikipedia.org', port=443): Max retries exceeded with url: /w/api.php?action=query&format=json&list=search&srsearch=data (Caused by SSLError(SSLCertVerificationError(1, '[SSL: CERTIFICATE_VERIFY_FAILED] certificate verify failed: unable to get local issuer certificate (_ssl.c:997)')))
2023-03-15 10:56:53,029 INFO 127.0.0.1 - - [15/Mar/2023 10:56:53] "[35m[1mGET /?q=data HTTP/1.1[0m" 500 -
2023-03-15 10:56:53,063 INFO 127.0.0.1 - - [15/Mar/2023 10:56:53] "[36mGET /?__debugger__=yes&cmd=resource&f=style.css HTTP/1.1[0m" 304 -
2023-03-15 10:56:53,077 INFO 127.0.0.1 - - [15/Mar/2023 10:56:53] "[36mGET /?__debugger__=yes&cmd=resource&f=debugger.js HTTP/1.1[0m" 304 -
2023-03-15 10:56:53,119 INFO 127.0.0.1 - - [15/Mar/2023 10:56:53] "[36mGET /?__debugger__=yes&cmd=resource&f=console.png HTTP/1.1[0m" 304 -
2023-03-15 10:56:53,157 INFO 127.0.0.1 - - [15/Mar/2023 10:56:53] "[36mGET /?__debugger__=yes&cmd=resource&f=console.png HTTP/1.1[0m" 304 -
2023-03-15 10:57:29,919 DEBUG Starting new HTTPS connection (1): en.wikipedia.org:443
2023-03-15 10:57:31,413 DEBUG https://en.wikipedia.org:443 "GET /w/api.php HTTP/1.1" 200 None
2023-03-15 10:57:31,436 INFO [31m[1mWARNING: This is a development server. Do not use it in a production deployment. Use a production WSGI server instead.[0m
 * Running on http://127.0.0.1:5000
2023-03-15 10:57:31,437 INFO [33mPress CTRL+C to quit[0m
2023-03-15 10:57:31,438 INFO  * Restarting with stat
2023-03-15 10:57:32,317 DEBUG Starting new HTTPS connection (1): en.wikipedia.org:443
2023-03-15 10:57:33,849 DEBUG https://en.wikipedia.org:443 "GET /w/api.php HTTP/1.1" 200 None
2023-03-15 10:57:33,862 WARNING  * Debugger is active!
2023-03-15 10:57:33,866 INFO  * Debugger PIN: 220-726-321
2023-03-15 10:57:33,900 INFO No data in query, wiki.html has loaded
2023-03-15 10:57:33,910 INFO 127.0.0.1 - - [15/Mar/2023 10:57:33] "GET / HTTP/1.1" 200 -
2023-03-15 10:57:33,981 INFO 127.0.0.1 - - [15/Mar/2023 10:57:33] "[36mGET /static/styles.css HTTP/1.1[0m" 304 -
2023-03-15 10:57:47,919 DEBUG Starting new HTTPS connection (1): en.wikipedia.org:443
2023-03-15 10:57:48,363 ERROR issues loading the data HTTPSConnectionPool(host='en.wikipedia.org', port=443): Max retries exceeded with url: /w/api.php?action=query&format=json&list=search&srsearch=key (Caused by SSLError(SSLCertVerificationError(1, '[SSL: CERTIFICATE_VERIFY_FAILED] certificate verify failed: unable to get local issuer certificate (_ssl.c:997)')))
Traceback (most recent call last):
  File "C:\Users\E1002312\AppData\Local\Programs\Python\Python310\lib\site-packages\urllib3\connectionpool.py", line 703, in urlopen
    httplib_response = self._make_request(
  File "C:\Users\E1002312\AppData\Local\Programs\Python\Python310\lib\site-packages\urllib3\connectionpool.py", line 386, in _make_request
    self._validate_conn(conn)
  File "C:\Users\E1002312\AppData\Local\Programs\Python\Python310\lib\site-packages\urllib3\connectionpool.py", line 1042, in _validate_conn
    conn.connect()
  File "C:\Users\E1002312\AppData\Local\Programs\Python\Python310\lib\site-packages\urllib3\connection.py", line 419, in connect
    self.sock = ssl_wrap_socket(
  File "C:\Users\E1002312\AppData\Local\Programs\Python\Python310\lib\site-packages\urllib3\util\ssl_.py", line 449, in ssl_wrap_socket
    ssl_sock = _ssl_wrap_socket_impl(
  File "C:\Users\E1002312\AppData\Local\Programs\Python\Python310\lib\site-packages\urllib3\util\ssl_.py", line 493, in _ssl_wrap_socket_impl
    return ssl_context.wrap_socket(sock, server_hostname=server_hostname)
  File "C:\Users\E1002312\AppData\Local\Programs\Python\Python310\lib\ssl.py", line 513, in wrap_socket
    return self.sslsocket_class._create(
  File "C:\Users\E1002312\AppData\Local\Programs\Python\Python310\lib\ssl.py", line 1071, in _create
    self.do_handshake()
  File "C:\Users\E1002312\AppData\Local\Programs\Python\Python310\lib\ssl.py", line 1342, in do_handshake
    self._sslobj.do_handshake()
ssl.SSLCertVerificationError: [SSL: CERTIFICATE_VERIFY_FAILED] certificate verify failed: unable to get local issuer certificate (_ssl.c:997)

During handling of the above exception, another exception occurred:

Traceback (most recent call last):
  File "C:\Users\E1002312\AppData\Local\Programs\Python\Python310\lib\site-packages\requests\adapters.py", line 489, in send
    resp = conn.urlopen(
  File "C:\Users\E1002312\AppData\Local\Programs\Python\Python310\lib\site-packages\urllib3\connectionpool.py", line 787, in urlopen
    retries = retries.increment(
  File "C:\Users\E1002312\AppData\Local\Programs\Python\Python310\lib\site-packages\urllib3\util\retry.py", line 592, in increment
    raise MaxRetryError(_pool, url, error or ResponseError(cause))
urllib3.exceptions.MaxRetryError: HTTPSConnectionPool(host='en.wikipedia.org', port=443): Max retries exceeded with url: /w/api.php?action=query&format=json&list=search&srsearch=key (Caused by SSLError(SSLCertVerificationError(1, '[SSL: CERTIFICATE_VERIFY_FAILED] certificate verify failed: unable to get local issuer certificate (_ssl.c:997)')))

During handling of the above exception, another exception occurred:

Traceback (most recent call last):
  File "C:\Users\E1002312\OneDrive - Sanlam Life Insurance Limited\Desktop\SM Khama\Python-Flask\app.py", line 27, in home
    data = requests.get(URL,params={'action': 'query', 'format': 'json', 'list': 'search', 'srsearch': request.args.get('q')})
  File "C:\Users\E1002312\AppData\Local\Programs\Python\Python310\lib\site-packages\requests\api.py", line 73, in get
    return request("get", url, params=params, **kwargs)
  File "C:\Users\E1002312\AppData\Local\Programs\Python\Python310\lib\site-packages\requests\api.py", line 59, in request
    return session.request(method=method, url=url, **kwargs)
  File "C:\Users\E1002312\AppData\Local\Programs\Python\Python310\lib\site-packages\requests\sessions.py", line 587, in request
    resp = self.send(prep, **send_kwargs)
  File "C:\Users\E1002312\AppData\Local\Programs\Python\Python310\lib\site-packages\requests\sessions.py", line 701, in send
    r = adapter.send(request, **kwargs)
  File "C:\Users\E1002312\AppData\Local\Programs\Python\Python310\lib\site-packages\requests\adapters.py", line 563, in send
    raise SSLError(e, request=request)
requests.exceptions.SSLError: HTTPSConnectionPool(host='en.wikipedia.org', port=443): Max retries exceeded with url: /w/api.php?action=query&format=json&list=search&srsearch=key (Caused by SSLError(SSLCertVerificationError(1, '[SSL: CERTIFICATE_VERIFY_FAILED] certificate verify failed: unable to get local issuer certificate (_ssl.c:997)')))
2023-03-15 10:57:48,405 INFO 127.0.0.1 - - [15/Mar/2023 10:57:48] "[35m[1mGET /?q=key HTTP/1.1[0m" 500 -
2023-03-15 10:57:48,438 INFO 127.0.0.1 - - [15/Mar/2023 10:57:48] "[36mGET /?__debugger__=yes&cmd=resource&f=style.css HTTP/1.1[0m" 304 -
2023-03-15 10:57:48,442 INFO 127.0.0.1 - - [15/Mar/2023 10:57:48] "[36mGET /?__debugger__=yes&cmd=resource&f=debugger.js HTTP/1.1[0m" 304 -
2023-03-15 10:57:48,470 INFO 127.0.0.1 - - [15/Mar/2023 10:57:48] "[36mGET /?__debugger__=yes&cmd=resource&f=console.png HTTP/1.1[0m" 304 -
2023-03-15 11:01:38,519 INFO  * Detected change in 'C:\\Users\\E1002312\\OneDrive - Sanlam Life Insurance Limited\\Desktop\\SM Khama\\Python-Flask\\test_app.py', reloading
2023-03-15 11:02:55,502 DEBUG Starting new HTTPS connection (1): en.wikipedia.org:443
2023-03-15 11:02:57,551 DEBUG https://en.wikipedia.org:443 "GET /w/api.php HTTP/1.1" 200 None
